<?xml version="1.0" encoding="utf-8"?>
<!-- This URDF was automatically created by SolidWorks to URDF Exporter! Originally created by Stephen Brawner (brawner@gmail.com) 
     Commit Version: 1.6.0-4-g7f85cfe  Build Version: 1.6.7995.38578
     For more information, please see http://wiki.ros.org/sw_urdf_exporter -->
<robot
  name="Макет v2">
  <link
    name="base_link">
    <inertial>
      <origin
        xyz="0.024636 0.00068431 0.10638"
        rpy="0 0 0" />
      <mass
        value="5" />
      <inertia
        ixx="0.018097"
        ixy="8.6144E-05"
        ixz="6.7135E-05"
        iyy="0.0070038"
        iyz="-9.0076E-05"
        izz="0.01647" />
    </inertial>
    <visual>
      <origin
        xyz="0 0 0"
        rpy="0 0 0" />
      <geometry>
        <mesh
          filename="package://Макет v2/meshes/base_link.STL" />
      </geometry>
      <material
        name="">
        <color
          rgba="1 0 0 1" />
      </material>
    </visual>
    <collision>
      <origin
        xyz="0 0 0"
        rpy="0 0 0" />
      <geometry>
        <mesh
          filename="package://Макет v2/meshes/base_link.STL" />
      </geometry>
    </collision>
  </link>
  <link
    name="right_wheel">
    <inertial>
      <origin
        xyz="0 -8.6254E-14 0.013353"
        rpy="0 0 0" />
      <mass
        value="0.08" />
      <inertia
        ixx="3.6651E-05"
        ixy="9.6988E-21"
        ixz="-7.7529E-22"
        iyy="3.6651E-05"
        iyz="-1.1318E-16"
        izz="5.4175E-05" />
    </inertial>
    <visual>
      <origin
        xyz="0 0 0"
        rpy="0 0 0" />
      <geometry>
        <mesh
          filename="package://Макет v2/meshes/right_wheel.STL" />
      </geometry>
      <material
        name="">
        <color
          rgba="0 0 1 1" />
      </material>
    </visual>
    <collision>
      <origin
        xyz="0 0 0"
        rpy="0 0 0" />
      <geometry>
        <mesh
          filename="package://Макет v2/meshes/right_wheel.STL" />
      </geometry>
    </collision>
  </link>
  <joint
    name="rightwheel"
    type="continuous">
    <origin
      xyz="0.059075 -0.2 0.021"
      rpy="-1.5708 0 0" />
    <parent
      link="base_link" />
    <child
      link="right_wheel" />
    <axis
      xyz="0 0 1" />
    <limit
      effort="0"
      velocity="10" />
    <dynamics
      damping="0"
      friction="0" />
  </joint>
  <link
    name="left_wheel">
    <inertial>
      <origin
        xyz="6.8279E-15 -1.2143E-15 -0.013353"
        rpy="0 0 0" />
      <mass
        value="0.08" />
      <inertia
        ixx="3.6651E-05"
        ixy="-1.3538E-21"
        ixz="-8.9321E-18"
        iyy="3.6651E-05"
        iyz="1.5999E-18"
        izz="5.4175E-05" />
    </inertial>
    <visual>
      <origin
        xyz="0 0 0"
        rpy="0 0 0" />
      <geometry>
        <mesh
          filename="package://Макет v2/meshes/left_wheel.STL" />
      </geometry>
      <material
        name="">
        <color
          rgba="0 0 1 1" />
      </material>
    </visual>
    <collision>
      <origin
        xyz="0 0 0"
        rpy="0 0 0" />
      <geometry>
        <mesh
          filename="package://Макет v2/meshes/left_wheel.STL" />
      </geometry>
    </collision>
  </link>
  <joint
    name="leftwheel"
    type="continuous">
    <origin
      xyz="0.059075 0.2 0.021"
      rpy="-1.5708 0 0" />
    <parent
      link="base_link" />
    <child
      link="left_wheel" />
    <axis
      xyz="0 0 1" />
    <limit
      effort="0"
      velocity="10" />
    <dynamics
      damping="0"
      friction="0" />
  </joint>
  <link
    name="aruco_link">
    <inertial>
      <origin
        xyz="-0.0092221 -1.2598E-17 -0.044216"
        rpy="0 0 0" />
      <mass
        value="0.2" />
      <inertia
        ixx="0.00036111"
        ixy="-1.6666E-21"
        ixz="-6.4905E-05"
        iyy="0.0003976"
        iyz="1.3655E-19"
        izz="0.00040158" />
    </inertial>
    <visual>
      <origin
        xyz="0 0 0"
        rpy="0 0 0" />
      <geometry>
        <mesh
          filename="package://Макет v2/meshes/aruco_link.STL" />
      </geometry>
      <material
        name="">
        <color
          rgba="0 1 0 1" />
      </material>
    </visual>
    <collision>
      <origin
        xyz="0 0 0"
        rpy="0 0 0" />
      <geometry>
        <mesh
          filename="package://Макет v2/meshes/aruco_link.STL" />
      </geometry>
    </collision>
  </link>
  <joint
    name="aruco_to_base"
    type="fixed">
    <origin
      xyz="-0.0032264 0 0.411"
      rpy="0 0 0" />
    <parent
      link="base_link" />
    <child
      link="aruco_link" />
    <axis
      xyz="0 0 0" />
  </joint>
  <link
    name="lidar_link">
    <inertial>
      <origin
        xyz="0.0001471 4.608E-08 -0.015129"
        rpy="0 0 0" />
      <mass
        value="0.25" />
      <inertia
        ixx="9.5253E-06"
        ixy="4.0169E-10"
        ixz="2.4656E-08"
        iyy="9.4165E-06"
        iyz="-9.4826E-12"
        izz="1.7083E-05" />
    </inertial>
    <visual>
      <origin
        xyz="0 0 0"
        rpy="0 0 0" />
      <geometry>
        <mesh
          filename="package://Макет v2/meshes/lidar_link.STL" />
      </geometry>
      <material
        name="">
        <color
          rgba="1 1 1 1" />
      </material>
    </visual>
    <collision>
      <origin
        xyz="0 0 0"
        rpy="0 0 0" />
      <geometry>
        <mesh
          filename="package://Макет v2/meshes/lidar_link.STL" />
      </geometry>
    </collision>
  </link>
  <joint
    name="lidar_to_base"
    type="fixed">
    <origin
      xyz="-0.0032264 0 0.31758"
      rpy="0 0 0" />
    <parent
      link="base_link" />
    <child
      link="lidar_link" />
    <axis
      xyz="0 0 0" />
  </joint>
</robot>