<?xml version="1.0" encoding="utf-8"?>
<!-- This URDF was automatically created by SolidWorks to URDF Exporter! Originally created by Stephen Brawner (brawner@gmail.com) 
     Commit Version: 1.6.0-4-g7f85cfe  Build Version: 1.6.7995.38578
     For more information, please see http://wiki.ros.org/sw_urdf_exporter -->
<robot
  name="Макет">
  <link
    name="base_link">
    <inertial>
      <origin
        xyz="0.055795 0.00111 0.11345"
        rpy="0 0 0" />
      <mass
        value="5" />
      <inertia
        ixx="0.01219"
        ixy="0.00012117"
        ixz="0.00018358"
        iyy="0.0027513"
        iyz="-0.00011927"
        izz="0.012455" />
    </inertial>
    <visual>
      <origin
        xyz="0 0 0"
        rpy="0 0 0" />
      <geometry>
        <mesh
          filename="package://Макет/meshes/base_link.STL" />
      </geometry>
      <material
        name="">
        <color
          rgba="1 0 0 1" />
      </material>
    </visual>
    <collision>
      <origin
        xyz="0 0 0"
        rpy="0 0 0" />
      <geometry>
        <mesh
          filename="package://Макет/meshes/base_link.STL" />
      </geometry>
    </collision>
  </link>
  <link
    name="lidar_link">
    <inertial>
      <origin
        xyz="0.00012979 -6.6734E-06 -0.0079009"
        rpy="0 0 0" />
      <mass
        value="0.25" />
      <inertia
        ixx="9.5253E-06"
        ixy="6.45E-11"
        ixz="4.1315E-08"
        iyy="9.4166E-06"
        iyz="6.3454E-09"
        izz="1.7083E-05" />
    </inertial>
    <visual>
      <origin
        xyz="0 0 0"
        rpy="0 0 0" />
      <geometry>
        <mesh
          filename="package://Макет/meshes/lidar_link.STL" />
      </geometry>
      <material
        name="">
        <color
          rgba="0 1 0 1" />
      </material>
    </visual>
    <collision>
      <origin
        xyz="0 0 0"
        rpy="0 0 0" />
      <geometry>
        <mesh
          filename="package://Макет/meshes/lidar_link.STL" />
      </geometry>
    </collision>
  </link>
  <joint
    name="lidar_to_base"
    type="fixed">
    <origin
      xyz="0.005563 0.002859 0.30015"
      rpy="0 0 0" />
    <parent
      link="base_link" />
    <child
      link="lidar_link" />
    <axis
      xyz="0 0 0" />
    <limit
      effort="0"
      velocity="0" />
    <dynamics
      damping="0"
      friction="0" />
  </joint>
  <link
    name="right_wheel">
    <inertial>
      <origin
        xyz="8.3267E-17 0 0.013353"
        rpy="0 0 0" />
      <mass
        value="0.08" />
      <inertia
        ixx="3.6651E-05"
        ixy="1.1089E-20"
        ixz="1.0295E-19"
        iyy="3.6651E-05"
        iyz="2.2675E-21"
        izz="5.4175E-05" />
    </inertial>
    <visual>
      <origin
        xyz="0 0 0"
        rpy="0 0 0" />
      <geometry>
        <mesh
          filename="package://Макет/meshes/right_wheel.STL" />
      </geometry>
      <material
        name="">
        <color
          rgba="0 0 1 1" />
      </material>
    </visual>
    <collision>
      <origin
        xyz="0 0 0"
        rpy="0 0 0" />
      <geometry>
        <mesh
          filename="package://Макет/meshes/right_wheel.STL" />
      </geometry>
    </collision>
  </link>
  <joint
    name="rightwheel"
    type="continuous">
    <origin
      xyz="0.059148 -0.2 0.021"
      rpy="-1.5708 0 0" />
    <parent
      link="base_link" />
    <child
      link="right_wheel" />
    <axis
      xyz="0 0 1" />
    <limit
      effort="0"
      velocity="10" />
    <dynamics
      damping="0"
      friction="0" />
  </joint>
  <link
    name="left_wheel">
    <inertial>
      <origin
        xyz="3.8886E-14 3.645E-14 0.38665"
        rpy="0 0 0" />
      <mass
        value="0.08" />
      <inertia
        ixx="3.6651E-05"
        ixy="-1.2633E-21"
        ixz="-9.0385E-18"
        iyy="3.6651E-05"
        iyz="7.177E-19"
        izz="5.4175E-05" />
    </inertial>
    <visual>
      <origin
        xyz="0 0 0"
        rpy="0 0 0" />
      <geometry>
        <mesh
          filename="package://Макет/meshes/left_wheel.STL" />
      </geometry>
      <material
        name="">
        <color
          rgba="0 0 1 1" />
      </material>
    </visual>
    <collision>
      <origin
        xyz="0 0 0"
        rpy="0 0 0" />
      <geometry>
        <mesh
          filename="package://Макет/meshes/left_wheel.STL" />
      </geometry>
    </collision>
  </link>
  <joint
    name="leftwheel"
    type="continuous">
    <origin
      xyz="0.059148 -0.2 0.021"
      rpy="-1.5708 0 0" />
    <parent
      link="base_link" />
    <child
      link="left_wheel" />
    <axis
      xyz="0 0 1" />
    <limit
      effort="0"
      velocity="10" />
    <dynamics
      damping="0"
      friction="0" />
  </joint>
</robot>